Traceback (most recent call last):
  File "/Users/sts/anaconda3/envs/ivans/lib/python3.11/site-packages/nbclient/client.py", line 782, in _async_poll_for_reply
    msg = await ensure_async(self.kc.shell_channel.get_msg(timeout=new_timeout))
          ^^^^^^^^^^^^^^^^^^^^^^^^^^^^^^^^^^^^^^^^^^^^^^^^^^^^^^^^^^^^^^^^^^^^^^
  File "/Users/sts/anaconda3/envs/ivans/lib/python3.11/site-packages/jupyter_core/utils/__init__.py", line 198, in ensure_async
    result = await obj
             ^^^^^^^^^
  File "/Users/sts/anaconda3/envs/ivans/lib/python3.11/site-packages/jupyter_client/channels.py", line 313, in get_msg
    raise Empty
_queue.Empty

During handling of the above exception, another exception occurred:

Traceback (most recent call last):
  File "/Users/sts/anaconda3/envs/ivans/lib/python3.11/site-packages/jupyter_cache/executors/utils.py", line 58, in single_nb_execution
    executenb(
  File "/Users/sts/anaconda3/envs/ivans/lib/python3.11/site-packages/nbclient/client.py", line 1314, in execute
    return NotebookClient(nb=nb, resources=resources, km=km, **kwargs).execute()
           ^^^^^^^^^^^^^^^^^^^^^^^^^^^^^^^^^^^^^^^^^^^^^^^^^^^^^^^^^^^^^^^^^^^^^
  File "/Users/sts/anaconda3/envs/ivans/lib/python3.11/site-packages/jupyter_core/utils/__init__.py", line 165, in wrapped
    return loop.run_until_complete(inner)
           ^^^^^^^^^^^^^^^^^^^^^^^^^^^^^^
  File "/Users/sts/anaconda3/envs/ivans/lib/python3.11/asyncio/base_events.py", line 654, in run_until_complete
    return future.result()
           ^^^^^^^^^^^^^^^
  File "/Users/sts/anaconda3/envs/ivans/lib/python3.11/site-packages/nbclient/client.py", line 709, in async_execute
    await self.async_execute_cell(
  File "/Users/sts/anaconda3/envs/ivans/lib/python3.11/site-packages/nbclient/client.py", line 1005, in async_execute_cell
    exec_reply = await self.task_poll_for_reply
                 ^^^^^^^^^^^^^^^^^^^^^^^^^^^^^^
  File "/Users/sts/anaconda3/envs/ivans/lib/python3.11/site-packages/nbclient/client.py", line 806, in _async_poll_for_reply
    error_on_timeout_execute_reply = await self._async_handle_timeout(timeout, cell)
                                     ^^^^^^^^^^^^^^^^^^^^^^^^^^^^^^^^^^^^^^^^^^^^^^^
  File "/Users/sts/anaconda3/envs/ivans/lib/python3.11/site-packages/nbclient/client.py", line 856, in _async_handle_timeout
    raise CellTimeoutError.error_from_timeout_and_cell(
nbclient.exceptions.CellTimeoutError: A cell timed out while it was being executed, after 30 seconds.
The message was: Cell execution timed out.
Here is a preview of the cell contents:
-------------------
['vbin = npy.linspace(-30,30,241)    # velocity bins for 1D histogram plots', 'vbin2 = npy.linspace (-30,30,961)  # velocity bins for 2D histograms', '', '# limits for number of collisions per bin color scale', 'cmin=1']
...
['plt.subplots_adjust(hspace=0.22,wspace=0.22,left=0.07,right=0.99,top=0.92,bottom=0.07)', '', "plt.savefig(plotdir+'Fig19-rel_v_hist_022GTJf6hydrogas.pdf',dpi=1200,pad_inches=0.1,bbox_inches='tight')", "plt.savefig(plotdir+'Fig19-rel_v_hist_022GTJf6hydrogas.png',dpi=1200,pad_inches=0.1,bbox_inches='tight')", 'plt.show()']
-------------------

